Workbook
Name liste_Country_Origin: #REF!
Name Liste_equipment: [1]!T_equipment_list[List equipement - Eng]
Name Liste_Maintenance_type: [2]!T_Type_maintenance[Maintenance type]
Name liste_RMPACK: #REF!
Name liste_supplier_RM: #REF!
Name Liste_Unité: #REF!
Name Partenaire: #REF!
Name Purchase_type: #REF!
Name Selec_annee: #REF!
Name selec_mois: #REF!

Sheet Sales
B2: Partner | C2: Année | D2: Mois | E2: Product (make your choice in the list) | F2: New Product | G2: Customer (make your choice in the list) | H2: New Customer | I2: Sold Quantity | J2: Unit | K2: Destination (make your choice in the list) | L2: New destination
B3: InnoFaso | C3: 2020 | D3: Jan | E3: ENOV'NUTRIBUTTER® | G3: Centre De Développement Pour Enfant (Cde) | I3: 22.68 | J3: Kg | K3: BURKINA FASO
B4: InnoFaso | C4: 2020 | D4: Jan | E4: PLUMPY’NUT® | G4: Hopital Baptiste Biblique | I4: 69 | J4: Kg | K4: TOGO
B5: InnoFaso | C5: 2020 | D5: Jan | E5: PLUMPY’NUT® | G5: UNICEF Burkina Faso | I5: 71760 | J5: Kg | K5: BURKINA FASO
B6: InnoFaso | C6: 2020 | D6: Feb | E6: PLUMPY’NUT® | G6: UNICEF Burkina Faso | I6: 231039.6 | J6: Kg | K6: BURKINA FASO
B7: InnoFaso | C7: 2020 | D7: Feb | E7: PLUMPY’NUT® | G7: WFP - HQ (International) | I7: 110400 | J7: Kg | K7: NIGER
B8: InnoFaso | C8: 2020 | D8: Feb | E8: PLUMPY'SUP™ | G8: ICRC | I8: 750 | J8: Kg | K8: MALI
B9: InnoFaso | C9: 2020 | D9: Feb | E9: PLUMPY’NUT® | G9: Centre De Développement Pour Enfant (Cde) | I9: 13.8 | J9: Kg | K9: BURKINA FASO
B10: InnoFaso | C10: 2020 | D10: Mar | E10: PLUMPY’NUT® | G10: Centre De Développement Pour Enfant (Cde) | I10: 27.6 | J10: Kg | K10: BURKINA FASO
B11: InnoFaso | C11: 2020 | D11: Mar | E11: PLUMPY'SUP™ | G11: Centre De Développement Pour Enfant (Cde) | I11: 27.6 | J11: Kg | K11: BURKINA FASO
B12: InnoFaso | C12: 2020 | D12: Mar | E12: ENOV'NUTRIBUTTER® | G12: Centre De Développement Pour Enfant (Cde) | I12: 11.34 | J12: Kg | K12: BURKINA FASO
B13: InnoFaso | C13: 2020 | D13: Apr | E13: PLUMPY’NUT® | G13: MSF | I13: 690 | J13: Kg | K13: BURKINA FASO
B14: InnoFaso | C14: 2020 | D14: Apr | E14: PLUMPY’NUT® | G14: UNICEF Burkina Faso | I14: 117300 | J14: Kg | K14: BURKINA FASO
... B193: InnoFaso | C193: 2023 | D193: Jan | E193: ENOV'NUTRIBUTTER® | G193: Centre De Développement Pour Enfant (Cde) | I193: 11 | J193: Kg | K193: BURKINA FASO

Sheet Procurement
B2: Partner | C2: Année | D2: Mois | E2: Raw material / packaging (make your choice in the list) | F2: New Raw material /Packaging (Only if the product is not in the list) | G2: Supplier (make your choice in the list) | H2: New supplier | I2: Country of origin of the raw material / Packaging (make your choice in the list) | J2: New country of origin | K2: Quantity | L2: Unit | M2: Purchase type (make your choice in the list)
B3: InnoFaso | C3: 2020 | D3: Jan | E3: ROASTED PEANUT | G3: Niza | I3: FRANCE | K3: 48000 | L3: Kg | M3: Imported raw material
B4: InnoFaso | C4: 2020 | D4: Jan | E4: MILK POWDER | G4: Nutriset - Lactalis | I4: FRANCE | K4: 73500 | L4: Kg | M4: Imported raw material
B5: InnoFaso | C5: 2020 | D5: Jan | E5: RAPESEED OIL | G5: Nutriset Sas | I5: GERMANY | K5: 16560 | L5: Kg | M5: Imported raw material
B6: InnoFaso | C6: 2020 | D6: Jan | E6: PREMIX PNUT | G6: Nutriset Sas | I6: POLAND | K6: 7200 | L6: Kg | M6: Imported raw material
B7: InnoFaso | C7: 2020 | D7: Jan | E7: NATA 5 | G7: Nutriset Sas | I7: FRANCE | K7: 3375 | L7: Kg | M7: Imported raw material
B8: InnoFaso | C8: 2020 | D8: Jan | E8: SACHET FILM PNUT | G8: Simpa Solutions | I8: IVORY COAST | K8: 268950 | L8: m² | M8: Imported raw material
B9: InnoFaso | C9: 2020 | D9: Jan | E9: SUGAR | G9: Sn Sosuco | I9: BURKINA FASO | K9: 50000 | L9: Kg | M9: Bought and produced locally
B10: InnoFaso | C10: 2020 | D10: Feb | E10: ROASTED PEANUT | G10: Niza | I10: ARGENTINA | K10: 48000 | L10: Kg | M10: Imported raw material
B11: InnoFaso | C11: 2020 | D11: Feb | E11: ROASTED PEANUT | G11: JL SA | I11: ARGENTINA | K11: 40000 | L11: Kg | M11: Imported raw material
B12: InnoFaso | C12: 2020 | D12: Feb | E12: WHEY | G12: Nutriset - Lactalis | I12: FRANCE | K12: 48000 | L12: Kg | M12: Imported raw material
B13: InnoFaso | C13: 2020 | D13: Feb | E13: MILK POWDER | G13: Nutriset - Lactalis | I13: FRANCE | K13: 49500 | L13: Kg | M13: Imported raw material
B14: InnoFaso | C14: 2020 | D14: Feb | E14: PALM OIL | G14: TBI | I14: MALAYSIA | K14: 67200 | L14: Kg | M14: Imported raw material
... B228: InnoFaso | C228: 2023 | D228: Jan | E228: SUGAR | G228: Sn Sosuco | I228: BURKINA FASO | K228: 90000 | L228: kg | M228: Local

Sheet Achat - Purchase FP
B2: Partner | C2: Année | D2: Mois | E2: Finished product (make your choice in the list) | F2: New Finished product (Only if the product is not in the list) | G2: Finished Product producer | H2: New Producer (Only if the product is not in the list) | I2: Quantity | J2: Unit

Sheet Monthly Production data
B3: Partner | C3: Année | D3: Mois | E3: Name of the production room (make your choice in the list) | F3: Product Name (make your choice in the list) | G3: New Finished product | H3: Quantity produced in the month (kg) | I3: Blend quantity in month (kg) | J3: Average number of hours per shift | K3: Number of shifts in the month | L3: Loss Rate
B4: InnoFaso | C4: 2020 | D4: Jan | E4: Room 1 | F4: PLUMPY’NUT® | H4: 111793.8
B5: InnoFaso | C5: 2020 | D5: Feb | E5: Room 1 | F5: PLUMPY’NUT® | H5: 192068
B6: InnoFaso | C6: 2020 | D6: Mar | E6: Room 1 | F6: PLUMPY’NUT® | H6: 135888.6
B7: InnoFaso | C7: 2020 | D7: Apr | E7: Room 1 | F7: PLUMPY’NUT® | H7: 190371
B8: InnoFaso | C8: 2020 | D8: Apr | E8: Room 1 | F8: PLUMPY'SUP™ | H8: 33855
B9: InnoFaso | C9: 2020 | D9: May | E9: Room 1 | F9: PLUMPY’NUT® | H9: 278657
B10: InnoFaso | C10: 2020 | D10: Jun | E10: Room 1 | F10: PLUMPY’NUT® | H10: 15000.6
B11: InnoFaso | C11: 2020 | D11: Jun | E11: Room 1 | F11: PLUMPY'SUP™ | H11: 166335
B12: InnoFaso | C12: 2020 | D12: Jul | E12: Room 1 | F12: PLUMPY’NUT® | H12: 327653
B13: InnoFaso | C13: 2020 | D13: Aug | E13: Room 1 | F13: PLUMPY’NUT® | H13: 289896.6
B14: InnoFaso | C14: 2020 | D14: Sept | E14: Room 1 | F14: PLUMPY’NUT® | H14: 163585.2
B15: InnoFaso | C15: 2020 | D15: Sept | E15: Room 1 | F15: PLUMPY'SUP™ | H15: 9045
... B47: InnoFaso | C47: 2022 | D47: Dec | E47: Room 1 | F47: PLUMPY’NUT® | H47: 365010
B48: InnoFaso | C48: 2023 | D48: Jan | E48: Room 1 | F48: PLUMPY’NUT® | H48: 382825.8 | I48: 386050 | J48: 8 | K48: 81 | L48: 0.0084

Sheet Monthly Production shutdown
B2: Partner | C2: Année | D2: Mois | E2: Name of the production room | F2: Shutdown Type | G2: New shutdown reason | H2: Days of shutdown | I2: Comments (free field)
B3: InnoFaso | C3: 2020 | D3: Jan | E3: All | F3: Technical machine problem | H3: 5 | I3: Refection armoire électrique générale de l'usine
B4: InnoFaso | C4: 2020 | D4: Jan | E4: All | F4: Technical machine problem | H4: 4 | I4: Thermorégulateur en panne - Pret d'un microcontrolleur de température chez STA
B5: InnoFaso | C5: 2020 | D5: Mar | E5: All | F5: Cleaning | H5: 1 | I5: Grand nettoyage salle poudre et désinfection
B6: InnoFaso | C6: 2020 | D6: Apr | E6: All | F6: Raw material shortage | H6: 0
B7: InnoFaso | C7: 2020 | D7: Jun | E7: All | F7: Technical machine problem | H7: 1 | I7: Maintenance préventive de la Pompe Chaudière ( thermorégulateur)
B8: InnoFaso | C8: 2020 | D8: Jun | E8: All | F8: Maintenance Spare parts shortage | H8: 7 | I8: Nettoyage profond de l'usine, Maintenance préventive de la CTA et désinfection
B9: InnoFaso | C9: 2020 | D9: Sept | E9: All | F9: Raw material shortage | H9: 11 | I9: Rupture matières prmières Farine de Soja et Prémix Pnut
B10: InnoFaso | C10: 2020 | D10: Oct | E10: All | F10: Raw material shortage | H10: 2 | I10: Panne de la pompe SPX
B11: InnoFaso | C11: 2020 | D11: Nov | E11: All | F11: Cleaning | H11: 1 | I11: Panne de la pompe SPX
B12: InnoFaso | C12: 2021 | D12: Jan | E12: All | F12: Cleaning | H12: 6 | I12: Nettoyage après congés annuels
B13: InnoFaso | C13: 2021 | D13: Mar | E13: All | F13: Factory works | H13: 3 | I13: Maintenance préventive annuelle
B14: InnoFaso | C14: 2021 | D14: Mar | E14: All | F14: External environment problem | H14: 1 | I14: Team building
B15: InnoFaso | C15: 2021 | D15: Apr | E15: All | F15: Raw material shortage | H15: 12 | I15: Maintenance préventive annuelle des équipements
B16: InnoFaso | C16: 2021 | D16: Apr | E16: All | F16: Raw material shortage | H16: 5 | I16: Manque d'huile de palme
B17: InnoFaso | C17: 2021 | D17: Jul | E17: All | F17: Technical machine problem | H17: 3 | I17: Court Circuit / feu câbles de commande armoire électrique thermisation
B18: InnoFaso | C18: 2021 | D18: Aug | E18: All | F18: Raw material shortage | H18: 1 | I18: Nettoyage profond changement de produit
... B24: InnoFaso | C24: 2022 | D24: Jan | E24: All | F24: External environment problem | H24: 2 | I24: Tensions politiques (Coup d'état)
B25: InnoFaso | C25: 2022 | D25: Feb | E25: All | F25: Raw material shortage | H25: 11
B26: InnoFaso | C26: 2022 | D26: Mar | E26: All | F26: Raw material shortage | H26: 6
B27: InnoFaso | C27: 2022 | D27: Aug | E27: All | F27: Raw material shortage | H27: 2 | I27: Rupture huile de palme et travaux usine
B28: InnoFaso | C28: 2022 | D28: Sept | E28: All | F28: Factory works | H28: 7 | I28: Rupture Huile de palme - Anticipation des travaux d'usine
B29: InnoFaso | C29: 2022 | D29: Oct | E29: All | F29: Factory works | H29: 6 | I29: Maintenance préventive annuelle et augmentation de capacité
B30: InnoFaso | C30: 2022 | D30: Nov | E30: All | F30: Raw material shortage | H30: 8 | I30: maintenance préventive annuelle et augmentation de capacité
B31: InnoFaso | C31: 2022 | D31: Nov | E31: All | F31: Technical machine problem | H31: 2 | I31: Pompe SPX prémélange défaillante

Sheet T_Maint_Innofaso
A1: Partner | B1: Année | C1: Mois | D1: Equipment | E1: New Equipment | F1: Maintenance Type | G1: Number of hours | H1: Description (free field)
A2: InnoFaso | B2: 2022 | C2: Jan | D2: Others equipments | F2: Preventive | G2: 6 | H2: CTA et groupe froid; maintenance hebdo
A3: InnoFaso | B3: 2022 | C3: Jan | D3: Others equipments | F3: Preventive | G3: 2 | H3: dust collector; maintenance hebdo
A4: InnoFaso | B4: 2022 | C4: Jan | D4: Air compressor | F4: Preventive | G4: 2 | H4: maintenance hebdo
A5: InnoFaso | B5: 2022 | C5: Jan | D5: Others equipments | F5: Preventive | G5: 1 | H5: aerorefroidisseur; maintenance hebdo
A6: InnoFaso | B6: 2022 | C6: Jan | D6: Others equipments | F6: Preventive | G6: 1 | H6: sécheur frigorifique; maintenance hebdo
A7: InnoFaso | B7: 2022 | C7: Jan | D7: Packing machine | F7: Preventive | G7: 4 | H7: L1/L2:maintenance hebdo
A8: InnoFaso | B8: 2022 | C8: Jan | D8: Others equipments | F8: Preventive | G8: 1 | H8: cuve peson; controle hebdo
A9: InnoFaso | B9: 2022 | C9: Jan | D9: Filling machine | F9: Preventive | G9: 2 | H9: L1/L2:maintenance hebdo
A10: InnoFaso | B10: 2022 | C10: Jan | D10: Others equipments | F10: Preventive | G10: 2 | H10: DPM1/DPM2: maintenance hebdo
A11: InnoFaso | B11: 2022 | C11: Jan | D11: Sachet Printer - Carton Printer | F11: Preventive | G11: 2 | H11: L1/L2:nettoyage et réglage
A12: InnoFaso | B12: 2022 | C12: Jan | D12: Others equipments | F12: Preventive | G12: 1 | H12: extracteur d'air: maintenance mensuelle
A13: InnoFaso | B13: 2022 | C13: Jan | D13: Others equipments | F13: Preventive | G13: 1 | H13: lampe UV; maintenance mensuelle
... A333: InnoFaso | B333: 2021 | C333: Jan | D333: Premixing heat treatment | F333: Preventive | G333: 1 | H333: vase d'eau. remplissage
A334: InnoFaso | B334: 2021 | C334: Jan | D334: Others equipments | F334: Preventive | G334: 0
A335: InnoFaso | B335: 2021 | C335: Jan | D335: Mixer | F335: Preventive | G335: 3 | H335: Nettoyage tuyauterie
A336: InnoFaso | B336: 2021 | C336: Jan | D336: Others equipments | F336: Preventive | G336: 0.7 | H336: Maintenance aerorefroidisseur
A337: InnoFaso | B337: 2021 | C337: Jan | D337: Grinder - Vibroreactor | F337: Preventive | G337: 6.5 | H337: B3.changement de manchon de guidage et joints.
A338: InnoFaso | B338: 2021 | C338: Jan | D338: Air compressor | F338: Preventive | G338: 1.5 | H338: Maintenance hebdomadaire
A339: InnoFaso | B339: 2021 | C339: Jan | D339: Conveyor | F339: Preventive | G339: 1.5 | H339: Cv1. Changement de moteur
A340: InnoFaso | B340: 2021 | C340: Jan | D340: Filling machine | F340: Corrective | G340: 3.3 | H340: L1. Réparation et changement capteur kinetrol
A341: InnoFaso | B341: 2021 | C341: Jan | D341: Premixing heat treatment | F341: Corrective | G341: 3.9 | H341: Réparation spx et debit
A342: InnoFaso | B342: 2021 | C342: Jan | D342: Packing machine | F342: Corrective | G342: 1.25 | H342: L1.remplacement de résistance verticale et tuyaux d'air
A343: InnoFaso | B343: 2021 | C343: Feb | D343: Main electrical panel | F343: Preventive | G343: 1.5 | H343: optinut. EN;contrôle de temps de mélange et résistance de chauffe.
A344: InnoFaso | B344: 2021 | C344: Feb | D344: Others equipments | F344: Preventive | G344: 1 | H344: maintenance hebdomadaire
A345: InnoFaso | B345: 2021 | C345: Feb | D345: Grinder - Vibroreactor | F345: Preventive | G345: 0.75 | H345: EN; contrôle mensuel des broyeurs 1,2,3.
A346: InnoFaso | B346: 2021 | C346: Feb | D346: Air compressor | F346: Preventive | G346: 2 | H346: maintenance hebdomadaire
... A396: InnoFaso | B396: 2021 | C396: Apr | D396: Grinder - Vibroreactor | F396: Preventive | G396: 2 | H396: broyeur 3:maintenance gle.
A397: InnoFaso | B397: 2021 | C397: Apr | D397: Premixing heat treatment | F397: Preventive | G397: 12
A398: InnoFaso | B398: 2021 | C398: Apr | D398: Premixing heat treatment | F398: Preventive | G398: 6 | H398: cuve additif:maintenance gle.
A399: InnoFaso | B399: 2021 | C399: Apr | D399: Premixing heat treatment | F399: Preventive | G399: 10 | H399: thermorégulateur:maintenance gle.
A400: InnoFaso | B400: 2021 | C400: Apr | D400: Premixing heat treatment | F400: Preventive | G400: 2 | H400: cuve tampon:maintenance gle.
A401: InnoFaso | B401: 2021 | C401: Apr | D401: Premixing heat treatment | F401: Preventive | G401: 8 | H401: pompe spx:maintenance gle.
A402: InnoFaso | B402: 2021 | C402: Apr | D402: Premixing heat treatment | F402: Preventive | G402: 2 | H402: optinut:maintenance gle.
A403: InnoFaso | B403: 2021 | C403: Apr | D403: Others equipments | F403: Preventive | G403: 4 | H403: spx produit fini:maintenance gle.
A404: InnoFaso | B404: 2021 | C404: Apr | D404: Others equipments | F404: Preventive | G404: 7 | H404: filtre produit fini:maintenance gle.
A405: InnoFaso | B405: 2021 | C405: Apr | D405: Grinder - Vibroreactor | F405: Preventive | G405: 3.25 | H405: broyeur 3:maintenance gle.
A406: InnoFaso | B406: 2021 | C406: Apr | D406: Mixer | F406: Preventive | G406: 4.5 | H406: maintenance générale annuelle
A407: InnoFaso | B407: 2021 | C407: Apr | D407: Filling machine | F407: Preventive | G407: 6 | H407: doseuse 2:maintenance gle.
A408: InnoFaso | B408: 2021 | C408: Apr | D408: Pre-mixing hopper | F408: Preventive | G408: 8 | H408: maintenance générale annuelle
...

Sheet compilation
K1: PS-ME-EN-SDM-A
A2: Suivi des Données de la maintenance des équipements
A3: Créée le : 01/01/2024 | G3: Modifié le : | K3: Page 1/1
A4: Emetteur : T. COMPAORE Date : 01/01/2024 Fonction : RT Signature : | G4: Vérificateur : C.Christophe Date : 01/01/2024 Fonction : RQRD Signature : | K4: Approbateur : O. COULIBALY Date : 02/01/2024 Fonction : DG Signature :
A5: Destinataires : DG, RAF, CL, RT, RQRD, CCQ,CAQM, AAQM,CM,AM,CQCP
A7: ANNEE | B7: MOIS | C7: TYPE DE MAINTENANCE | D7: EQUIPEMENTS
D8: Air compressor | E8: Conveyor | F8: Filling machine | G8: Grinder - Vibroreactor | H8: Mixer | I8: Others equipments | J8: Packing machine | K8: Premixing heat treatment | L8: Sachet Printer - Carton Printer | M8: Nitrogen generator - Filter | N8: Main electrical panel | O8: Finished Product Transfer Pump | P8: TOTAL | Q8: TOTAL GENERAL | R8: difficultés ou remarques | W8: actions | AB8: Responsable action | AC8: Délais
A9: 2025 | B9: Jan | C9: Preventive | D9: =SUMIFS(T_Maint_Innofaso!G:G,T_Maint_Innofaso!B:B,A$11,T_Maint_Innofaso!C:C,B9,T_Maint_Innofaso!F:F,C9,T_Maint_Innofaso!D:D,compilation!D$8) -> 5 | E9: =SUMIFS(T_Maint_Innofaso!G:G,T_Maint_Innofaso!B:B,A$11,T_Maint_Innofaso!C:C,B9,T_Maint_Innofaso!F:F,C9,T_Maint_Innofaso!D:D,E$8) -> 1 | F9: =SUMIFS(T_Maint_Innofaso!G:G,T_Maint_Innofaso!B:B,A$11,T_Maint_Innofaso!C:C,B9,T_Maint_Innofaso!F:F,C9,T_Maint_Innofaso!D:D,F$8) -> 3 | G9: =SUMIFS(T_Maint_Innofaso!G:G,T_Maint_Innofaso!B:B,A$11,T_Maint_Innofaso!C:C,B9,T_Maint_Innofaso!F:F,C9,T_Maint_Innofaso!D:D,G$8) -> 1 | H9: =SUMIFS(T_Maint_Innofaso!G:G,T_Maint_Innofaso!B:B,A$11,T_Maint_Innofaso!C:C,B9,T_Maint_Innofaso!F:F,C9,T_Maint_Innofaso!D:D,H$8) -> 1 | I9: =SUMIFS(T_Maint_Innofaso!G:G,T_Maint_Innofaso!B:B,A$11,T_Maint_Innofaso!C:C,B9,T_Maint_Innofaso!F:F,C9,T_Maint_Innofaso!D:D,I$8) -> 30.67 | J9: =SUMIFS(T_Maint_Innofaso!G:G,T_Maint_Innofaso!B:B,A$11,T_Maint_Innofaso!C:C,B9,T_Maint_Innofaso!F:F,C9,T_Maint_Innofaso!D:D,J$8) -> 9 | K9: =SUMIFS(T_Maint_Innofaso!G:G,T_Maint_Innofaso!B:B,A$11,T_Maint_Innofaso!C:C,B9,T_Maint_Innofaso!F:F,C9,T_Maint_Innofaso!D:D,K$8) -> 2 | L9: =SUMIFS(T_Maint_Innofaso!G:G,T_Maint_Innofaso!B:B,A$11,T_Maint_Innofaso!C:C,B9,T_Maint_Innofaso!F:F,C9,T_Maint_Innofaso!D:D,L$8) -> 0 | M9: =SUMIFS(T_Maint_Innofaso!G:G,T_Maint_Innofaso!B:B,A$11,T_Maint_Innofaso!C:C,B9,T_Maint_Innofaso!F:F,C9,T_Maint_Innofaso!D:D,M$8) -> 0 | N9: =SUMIFS(T_Maint_Innofaso!G:G,T_Maint_Innofaso!B:B,A$11,T_Maint_Innofaso!C:C,B9,T_Maint_Innofaso!F:F,C9,T_Maint_Innofaso!D:D,N$8) -> 0 | O9: =SUMIFS(T_Maint_Innofaso!G:G,T_Maint_Innofaso!B:B,A$11,T_Maint_Innofaso!C:C,B9,T_Maint_Innofaso!F:F,C9,T_Maint_Innofaso!D:D,O$8) -> 0 | P9: =SUM(D9:O9) -> 52.67 | Q9: =P9+P10 -> 96.72 | R9: problème d'oscillateur avec imprimante sachet L1 | W9: commande de pièce en cours | AB9: RT,LOG, | AC9: 45716
C10: Corrective | D10: =SUMIFS(T_Maint_Innofaso!G:G,T_Maint_Innofaso!B:B,A$11,T_Maint_Innofaso!C:C,B9,T_Maint_Innofaso!F:F,C10,T_Maint_Innofaso!D:D,compilation!D$8) -> 0 | E10: =SUMIFS(T_Maint_Innofaso!G:G,T_Maint_Innofaso!B:B,A$11,T_Maint_Innofaso!C:C,B9,T_Maint_Innofaso!F:F,C10,T_Maint_Innofaso!D:D,E$8) -> 0 | F10: =SUMIFS(T_Maint_Innofaso!G:G,T_Maint_Innofaso!B:B,A$11,T_Maint_Innofaso!C:C,B9,T_Maint_Innofaso!F:F,C10,T_Maint_Innofaso!D:D,F$8) -> 4.5 | G10: =SUMIFS(T_Maint_Innofaso!G:G,T_Maint_Innofaso!B:B,A$11,T_Maint_Innofaso!C:C,B9,T_Maint_Innofaso!F:F,C10,T_Maint_Innofaso!D:D,G$8) -> 0 | H10: =SUMIFS(T_Maint_Innofaso!G:G,T_Maint_Innofaso!B:B,A$11,T_Maint_Innofaso!C:C,B9,T_Maint_Innofaso!F:F,C10,T_Maint_Innofaso!D:D,H$8) -> 0 | I10: =SUMIFS(T_Maint_Innofaso!G:G,T_Maint_Innofaso!B:B,A$11,T_Maint_Innofaso!C:C,B9,T_Maint_Innofaso!F:F,C10,T_Maint_Innofaso!D:D,I$8) -> 0 | J10: =SUMIFS(T_Maint_Innofaso!G:G,T_Maint_Innofaso!B:B,A$11,T_Maint_Innofaso!C:C,B9,T_Maint_Innofaso!F:F,C10,T_Maint_Innofaso!D:D,J$8) -> 15.9 | K10: =SUMIFS(T_Maint_Innofaso!G:G,T_Maint_Innofaso!B:B,A$11,T_Maint_Innofaso!C:C,B9,T_Maint_Innofaso!F:F,C10,T_Maint_Innofaso!D:D,K$8) -> 10 | L10: =SUMIFS(T_Maint_Innofaso!G:G,T_Maint_Innofaso!B:B,A$11,T_Maint_Innofaso!C:C,B9,T_Maint_Innofaso!F:F,C10,T_Maint_Innofaso!D:D,L$8) -> 12.4 | M10: =SUMIFS(T_Maint_Innofaso!G:G,T_Maint_Innofaso!B:B,A$11,T_Maint_Innofaso!C:C,B9,T_Maint_Innofaso!F:F,C10,T_Maint_Innofaso!D:D,M$8) -> 0 | N10: =SUMIFS(T_Maint_Innofaso!G:G,T_Maint_Innofaso!B:B,A$11,T_Maint_Innofaso!C:C,B9,T_Maint_Innofaso!F:F,C10,T_Maint_Innofaso!D:D,N$8) -> 0 | O10: =SUMIFS(T_Maint_Innofaso!G:G,T_Maint_Innofaso!B:B,A$11,T_Maint_Innofaso!C:C,B9,T_Maint_Innofaso!F:F,C10,T_Maint_Innofaso!D:D,O$8) -> 1.25 | P10: =SUM(D10:O10) -> 44.05
A11: 2025 | B11: Feb | C11: Preventive | D11: =SUMIFS(T_Maint_Innofaso!G:G,T_Maint_Innofaso!B:B,A$11,T_Maint_Innofaso!C:C,B11,T_Maint_Innofaso!F:F,C11,T_Maint_Innofaso!D:D,compilation!D$8) -> 2 | E11: =SUMIFS(T_Maint_Innofaso!G:G,T_Maint_Innofaso!B:B,A$11,T_Maint_Innofaso!C:C,B11,T_Maint_Innofaso!F:F,C11,T_Maint_Innofaso!D:D,E$8) -> 1 | F11: =SUMIFS(T_Maint_Innofaso!G:G,T_Maint_Innofaso!B:B,A$11,T_Maint_Innofaso!C:C,B11,T_Maint_Innofaso!F:F,C11,T_Maint_Innofaso!D:D,F$8) -> 3 | G11: =SUMIFS(T_Maint_Innofaso!G:G,T_Maint_Innofaso!B:B,A$11,T_Maint_Innofaso!C:C,B11,T_Maint_Innofaso!F:F,C11,T_Maint_Innofaso!D:D,G$8) -> 1 | H11: =SUMIFS(T_Maint_Innofaso!G:G,T_Maint_Innofaso!B:B,A$11,T_Maint_Innofaso!C:C,B11,T_Maint_Innofaso!F:F,C11,T_Maint_Innofaso!D:D,H$8) -> 1 | I11: =SUMIFS(T_Maint_Innofaso!G:G,T_Maint_Innofaso!B:B,A$11,T_Maint_Innofaso!C:C,B11,T_Maint_Innofaso!F:F,C11,T_Maint_Innofaso!D:D,I$8) -> 31.07 | J11: =SUMIFS(T_Maint_Innofaso!G:G,T_Maint_Innofaso!B:B,A$11,T_Maint_Innofaso!C:C,B11,T_Maint_Innofaso!F:F,C11,T_Maint_Innofaso!D:D,J$8) -> 7 | K11: =SUMIFS(T_Maint_Innofaso!G:G,T_Maint_Innofaso!B:B,A$11,T_Maint_Innofaso!C:C,B11,T_Maint_Innofaso!F:F,C11,T_Maint_Innofaso!D:D,K$8) -> 1 | L11: =SUMIFS(T_Maint_Innofaso!G:G,T_Maint_Innofaso!B:B,A$11,T_Maint_Innofaso!C:C,B11,T_Maint_Innofaso!F:F,C11,T_Maint_Innofaso!D:D,L$8) -> 0 | M11: =SUMIFS(T_Maint_Innofaso!G:G,T_Maint_Innofaso!B:B,A$11,T_Maint_Innofaso!C:C,B11,T_Maint_Innofaso!F:F,C11,T_Maint_Innofaso!D:D,M$8) -> 0 | N11: =SUMIFS(T_Maint_Innofaso!G:G,T_Maint_Innofaso!B:B,A$11,T_Maint_Innofaso!C:C,B11,T_Maint_Innofaso!F:F,C11,T_Maint_Innofaso!D:D,N$8) -> 0 | O11: =SUMIFS(T_Maint_Innofaso!G:G,T_Maint_Innofaso!B:B,A$11,T_Maint_Innofaso!C:C,B11,T_Maint_Innofaso!F:F,C11,T_Maint_Innofaso!D:D,O$8) -> 0 | P11: =SUM(D11:O11) -> 47.07 | Q11: =P11+P12 -> 94.17 | R11: Ensacheuse L1 à l'arret manque de pièce. Plusieurs panne sur L4 | W11: reparation en mi-fevrier de l'imprimante | AB11: CM | AC11: 45716
C12: Corrective | D12: =SUMIFS(T_Maint_Innofaso!G:G,T_Maint_Innofaso!B:B,A$11,T_Maint_Innofaso!C:C,B11,T_Maint_Innofaso!F:F,C12,T_Maint_Innofaso!D:D,compilation!D$8) -> 0 | E12: =SUMIFS(T_Maint_Innofaso!G:G,T_Maint_Innofaso!B:B,A$11,T_Maint_Innofaso!C:C,B11,T_Maint_Innofaso!F:F,C12,T_Maint_Innofaso!D:D,E$8) -> 0 | F12: =SUMIFS(T_Maint_Innofaso!G:G,T_Maint_Innofaso!B:B,A$11,T_Maint_Innofaso!C:C,B11,T_Maint_Innofaso!F:F,C12,T_Maint_Innofaso!D:D,F$8) -> 0 | G12: =SUMIFS(T_Maint_Innofaso!G:G,T_Maint_Innofaso!B:B,A$11,T_Maint_Innofaso!C:C,B11,T_Maint_Innofaso!F:F,C12,T_Maint_Innofaso!D:D,G$8) -> 0 | H12: =SUMIFS(T_Maint_Innofaso!G:G,T_Maint_Innofaso!B:B,A$11,T_Maint_Innofaso!C:C,B11,T_Maint_Innofaso!F:F,C12,T_Maint_Innofaso!D:D,H$8) -> 0 | I12: =SUMIFS(T_Maint_Innofaso!G:G,T_Maint_Innofaso!B:B,A$11,T_Maint_Innofaso!C:C,B11,T_Maint_Innofaso!F:F,C12,T_Maint_Innofaso!D:D,I$8) -> 6.9 | J12: =SUMIFS(T_Maint_Innofaso!G:G,T_Maint_Innofaso!B:B,A$11,T_Maint_Innofaso!C:C,B11,T_Maint_Innofaso!F:F,C12,T_Maint_Innofaso!D:D,J$8) -> 15.3 | K12: =SUMIFS(T_Maint_Innofaso!G:G,T_Maint_Innofaso!B:B,A$11,T_Maint_Innofaso!C:C,B11,T_Maint_Innofaso!F:F,C12,T_Maint_Innofaso!D:D,K$8) -> 24.9 | L12: =SUMIFS(T_Maint_Innofaso!G:G,T_Maint_Innofaso!B:B,A$11,T_Maint_Innofaso!C:C,B11,T_Maint_Innofaso!F:F,C12,T_Maint_Innofaso!D:D,L$8) -> 0 | M12: =SUMIFS(T_Maint_Innofaso!G:G,T_Maint_Innofaso!B:B,A$11,T_Maint_Innofaso!C:C,B11,T_Maint_Innofaso!F:F,C12,T_Maint_Innofaso!D:D,M$8) -> 0 | N12: =SUMIFS(T_Maint_Innofaso!G:G,T_Maint_Innofaso!B:B,A$11,T_Maint_Innofaso!C:C,B11,T_Maint_Innofaso!F:F,C12,T_Maint_Innofaso!D:D,N$8) -> 0 | O12: =SUMIFS(T_Maint_Innofaso!G:G,T_Maint_Innofaso!B:B,A$11,T_Maint_Innofaso!C:C,B11,T_Maint_Innofaso!F:F,C12,T_Maint_Innofaso!D:D,O$8) -> 0 | P12: =SUM(D12:O12) -> 47.1
A13: 2025 | B13: Mar | C13: Preventive | D13: =SUMIFS(T_Maint_Innofaso!G:G,T_Maint_Innofaso!B:B,A$11,T_Maint_Innofaso!C:C,B13,T_Maint_Innofaso!F:F,C13,T_Maint_Innofaso!D:D,compilation!D$8) -> 2 | E13: =SUMIFS(T_Maint_Innofaso!G:G,T_Maint_Innofaso!B:B,A$11,T_Maint_Innofaso!C:C,B13,T_Maint_Innofaso!F:F,C13,T_Maint_Innofaso!D:D,E$8) -> 1 | F13: =SUMIFS(T_Maint_Innofaso!G:G,T_Maint_Innofaso!B:B,A$11,T_Maint_Innofaso!C:C,B13,T_Maint_Innofaso!F:F,C13,T_Maint_Innofaso!D:D,F$8) -> 34.5 | G13: =SUMIFS(T_Maint_Innofaso!G:G,T_Maint_Innofaso!B:B,A$11,T_Maint_Innofaso!C:C,B13,T_Maint_Innofaso!F:F,C13,T_Maint_Innofaso!D:D,G$8) -> 1 | H13: =SUMIFS(T_Maint_Innofaso!G:G,T_Maint_Innofaso!B:B,A$11,T_Maint_Innofaso!C:C,B13,T_Maint_Innofaso!F:F,C13,T_Maint_Innofaso!D:D,H$8) -> 1 | I13: =SUMIFS(T_Maint_Innofaso!G:G,T_Maint_Innofaso!B:B,A$11,T_Maint_Innofaso!C:C,B13,T_Maint_Innofaso!F:F,C13,T_Maint_Innofaso!D:D,I$8) -> 47.57 | J13: =SUMIFS(T_Maint_Innofaso!G:G,T_Maint_Innofaso!B:B,A$11,T_Maint_Innofaso!C:C,B13,T_Maint_Innofaso!F:F,C13,T_Maint_Innofaso!D:D,J$8) -> 20.5 | K13: =SUMIFS(T_Maint_Innofaso!G:G,T_Maint_Innofaso!B:B,A$11,T_Maint_Innofaso!C:C,B13,T_Maint_Innofaso!F:F,C13,T_Maint_Innofaso!D:D,K$8) -> 1 | L13: =SUMIFS(T_Maint_Innofaso!G:G,T_Maint_Innofaso!B:B,A$11,T_Maint_Innofaso!C:C,B13,T_Maint_Innofaso!F:F,C13,T_Maint_Innofaso!D:D,L$8) -> 0 | M13: =SUMIFS(T_Maint_Innofaso!G:G,T_Maint_Innofaso!B:B,A$11,T_Maint_Innofaso!C:C,B13,T_Maint_Innofaso!F:F,C13,T_Maint_Innofaso!D:D,M$8) -> 0 | N13: =SUMIFS(T_Maint_Innofaso!G:G,T_Maint_Innofaso!B:B,A$11,T_Maint_Innofaso!C:C,B13,T_Maint_Innofaso!F:F,C13,T_Maint_Innofaso!D:D,N$8) -> 0 | O13: =SUMIFS(T_Maint_Innofaso!G:G,T_Maint_Innofaso!B:B,A$11,T_Maint_Innofaso!C:C,B13,T_Maint_Innofaso!F:F,C13,T_Maint_Innofaso!D:D,O$8) -> 0 | P13: =SUM(D13:O13) -> 108.57 | Q13: =P13+P14 -> 139.57 | R13: changement de produit (ENB+) éssai difficile ayant nécéssité beaucoup de maintenance
C14: Corrective | D14: =SUMIFS(T_Maint_Innofaso!G:G,T_Maint_Innofaso!B:B,A$11,T_Maint_Innofaso!C:C,B13,T_Maint_Innofaso!F:F,C14,T_Maint_Innofaso!D:D,compilation!D$8) -> 0 | E14: =SUMIFS(T_Maint_Innofaso!G:G,T_Maint_Innofaso!B:B,A$11,T_Maint_Innofaso!C:C,B13,T_Maint_Innofaso!F:F,C14,T_Maint_Innofaso!D:D,E$8) -> 0 | F14: =SUMIFS(T_Maint_Innofaso!G:G,T_Maint_Innofaso!B:B,A$11,T_Maint_Innofaso!C:C,B13,T_Maint_Innofaso!F:F,C14,T_Maint_Innofaso!D:D,F$8) -> 0 | G14: =SUMIFS(T_Maint_Innofaso!G:G,T_Maint_Innofaso!B:B,A$11,T_Maint_Innofaso!C:C,B13,T_Maint_Innofaso!F:F,C14,T_Maint_Innofaso!D:D,G$8) -> 0.6 | H14: =SUMIFS(T_Maint_Innofaso!G:G,T_Maint_Innofaso!B:B,A$11,T_Maint_Innofaso!C:C,B13,T_Maint_Innofaso!F:F,C14,T_Maint_Innofaso!D:D,H$8) -> 0 | I14: =SUMIFS(T_Maint_Innofaso!G:G,T_Maint_Innofaso!B:B,A$11,T_Maint_Innofaso!C:C,B13,T_Maint_Innofaso!F:F,C14,T_Maint_Innofaso!D:D,I$8) -> 1.6 | J14: =SUMIFS(T_Maint_Innofaso!G:G,T_Maint_Innofaso!B:B,A$11,T_Maint_Innofaso!C:C,B13,T_Maint_Innofaso!F:F,C14,T_Maint_Innofaso!D:D,J$8) -> 26.8 | K14: =SUMIFS(T_Maint_Innofaso!G:G,T_Maint_Innofaso!B:B,A$11,T_Maint_Innofaso!C:C,B13,T_Maint_Innofaso!F:F,C14,T_Maint_Innofaso!D:D,K$8) -> 2 | L14: =SUMIFS(T_Maint_Innofaso!G:G,T_Maint_Innofaso!B:B,A$11,T_Maint_Innofaso!C:C,B13,T_Maint_Innofaso!F:F,C14,T_Maint_Innofaso!D:D,L$8) -> 0 | M14: =SUMIFS(T_Maint_Innofaso!G:G,T_Maint_Innofaso!B:B,A$11,T_Maint_Innofaso!C:C,B13,T_Maint_Innofaso!F:F,C14,T_Maint_Innofaso!D:D,M$8) -> 0 | N14: =SUMIFS(T_Maint_Innofaso!G:G,T_Maint_Innofaso!B:B,A$11,T_Maint_Innofaso!C:C,B13,T_Maint_Innofaso!F:F,C14,T_Maint_Innofaso!D:D,N$8) -> 0 | O14: =SUMIFS(T_Maint_Innofaso!G:G,T_Maint_Innofaso!B:B,A$11,T_Maint_Innofaso!C:C,B13,T_Maint_Innofaso!F:F,C14,T_Maint_Innofaso!D:D,O$8) -> 0 | P14: =SUM(D14:O14) -> 31
A15: 2025 | B15: Apr | C15: Preventive | D15: =SUMIFS(T_Maint_Innofaso!G:G,T_Maint_Innofaso!B:B,A$11,T_Maint_Innofaso!C:C,B15,T_Maint_Innofaso!F:F,C15,T_Maint_Innofaso!D:D,compilation!D$8) -> 2 | E15: =SUMIFS(T_Maint_Innofaso!G:G,T_Maint_Innofaso!B:B,A$11,T_Maint_Innofaso!C:C,B15,T_Maint_Innofaso!F:F,C15,T_Maint_Innofaso!D:D,E$8) -> 1 | F15: =SUMIFS(T_Maint_Innofaso!G:G,T_Maint_Innofaso!B:B,A$11,T_Maint_Innofaso!C:C,B15,T_Maint_Innofaso!F:F,C15,T_Maint_Innofaso!D:D,F$8) -> 6.5 | G15: =SUMIFS(T_Maint_Innofaso!G:G,T_Maint_Innofaso!B:B,A$11,T_Maint_Innofaso!C:C,B15,T_Maint_Innofaso!F:F,C15,T_Maint_Innofaso!D:D,G$8) -> 1 | H15: =SUMIFS(T_Maint_Innofaso!G:G,T_Maint_Innofaso!B:B,A$11,T_Maint_Innofaso!C:C,B15,T_Maint_Innofaso!F:F,C15,T_Maint_Innofaso!D:D,H$8) -> 1.5 | I15: =SUMIFS(T_Maint_Innofaso!G:G,T_Maint_Innofaso!B:B,A$11,T_Maint_Innofaso!C:C,B15,T_Maint_Innofaso!F:F,C15,T_Maint_Innofaso!D:D,I$8) -> 40.67 | J15: =SUMIFS(T_Maint_Innofaso!G:G,T_Maint_Innofaso!B:B,A$11,T_Maint_Innofaso!C:C,B15,T_Maint_Innofaso!F:F,C15,T_Maint_Innofaso!D:D,J$8) -> 9 | K15: =SUMIFS(T_Maint_Innofaso!G:G,T_Maint_Innofaso!B:B,A$11,T_Maint_Innofaso!C:C,B15,T_Maint_Innofaso!F:F,C15,T_Maint_Innofaso!D:D,K$8) -> 1.5 | L15: =SUMIFS(T_Maint_Innofaso!G:G,T_Maint_Innofaso!B:B,A$11,T_Maint_Innofaso!C:C,B15,T_Maint_Innofaso!F:F,C15,T_Maint_Innofaso!D:D,L$8) -> 0 | M15: =SUMIFS(T_Maint_Innofaso!G:G,T_Maint_Innofaso!B:B,A$11,T_Maint_Innofaso!C:C,B15,T_Maint_Innofaso!F:F,C15,T_Maint_Innofaso!D:D,M$8) -> 0 | N15: =SUMIFS(T_Maint_Innofaso!G:G,T_Maint_Innofaso!B:B,A$11,T_Maint_Innofaso!C:C,B15,T_Maint_Innofaso!F:F,C15,T_Maint_Innofaso!D:D,N$8) -> 0 | O15: =SUMIFS(T_Maint_Innofaso!G:G,T_Maint_Innofaso!B:B,A$11,T_Maint_Innofaso!C:C,B15,T_Maint_Innofaso!F:F,C15,T_Maint_Innofaso!D:D,O$8) -> 0 | P15: =SUM(D15:O15) -> 63.17 | Q15: =P15+P16 -> 102.92 | R15: panne sur L4 vers fin avril.panne du doseur. Problème resolu au bout de 10 jours environ | W15: demande de formation supplémentaires sur l'ensacheuse L4 | AB15: RT | AC15: 45838
C16: Corrective | D16: =SUMIFS(T_Maint_Innofaso!G:G,T_Maint_Innofaso!B:B,A$11,T_Maint_Innofaso!C:C,B15,T_Maint_Innofaso!F:F,C16,T_Maint_Innofaso!D:D,compilation!D$8) -> 6.4 | E16: =SUMIFS(T_Maint_Innofaso!G:G,T_Maint_Innofaso!B:B,A$11,T_Maint_Innofaso!C:C,B15,T_Maint_Innofaso!F:F,C16,T_Maint_Innofaso!D:D,E$8) -> 1 | F16: =SUMIFS(T_Maint_Innofaso!G:G,T_Maint_Innofaso!B:B,A$11,T_Maint_Innofaso!C:C,B15,T_Maint_Innofaso!F:F,C16,T_Maint_Innofaso!D:D,F$8) -> 0 | G16: =SUMIFS(T_Maint_Innofaso!G:G,T_Maint_Innofaso!B:B,A$11,T_Maint_Innofaso!C:C,B15,T_Maint_Innofaso!F:F,C16,T_Maint_Innofaso!D:D,G$8) -> 0 | H16: =SUMIFS(T_Maint_Innofaso!G:G,T_Maint_Innofaso!B:B,A$11,T_Maint_Innofaso!C:C,B15,T_Maint_Innofaso!F:F,C16,T_Maint_Innofaso!D:D,H$8) -> 0 | I16: =SUMIFS(T_Maint_Innofaso!G:G,T_Maint_Innofaso!B:B,A$11,T_Maint_Innofaso!C:C,B15,T_Maint_Innofaso!F:F,C16,T_Maint_Innofaso!D:D,I$8) -> 0.5 | J16: =SUMIFS(T_Maint_Innofaso!G:G,T_Maint_Innofaso!B:B,A$11,T_Maint_Innofaso!C:C,B15,T_Maint_Innofaso!F:F,C16,T_Maint_Innofaso!D:D,J$8) -> 28 | K16: =SUMIFS(T_Maint_Innofaso!G:G,T_Maint_Innofaso!B:B,A$11,T_Maint_Innofaso!C:C,B15,T_Maint_Innofaso!F:F,C16,T_Maint_Innofaso!D:D,K$8) -> 0 | L16: =SUMIFS(T_Maint_Innofaso!G:G,T_Maint_Innofaso!B:B,A$11,T_Maint_Innofaso!C:C,B15,T_Maint_Innofaso!F:F,C16,T_Maint_Innofaso!D:D,L$8) -> 3.85 | M16: =SUMIFS(T_Maint_Innofaso!G:G,T_Maint_Innofaso!B:B,A$11,T_Maint_Innofaso!C:C,B15,T_Maint_Innofaso!F:F,C16,T_Maint_Innofaso!D:D,M$8) -> 0 | N16: =SUMIFS(T_Maint_Innofaso!G:G,T_Maint_Innofaso!B:B,A$11,T_Maint_Innofaso!C:C,B15,T_Maint_Innofaso!F:F,C16,T_Maint_Innofaso!D:D,N$8) -> 0 | O16: =SUMIFS(T_Maint_Innofaso!G:G,T_Maint_Innofaso!B:B,A$11,T_Maint_Innofaso!C:C,B15,T_Maint_Innofaso!F:F,C16,T_Maint_Innofaso!D:D,O$8) -> 0 | P16: =SUM(D16:O16) -> 39.75
A17: 2025 | B17: May | C17: Preventive | D17: =SUMIFS(T_Maint_Innofaso!G:G,T_Maint_Innofaso!B:B,A$11,T_Maint_Innofaso!C:C,B17,T_Maint_Innofaso!F:F,C17,T_Maint_Innofaso!D:D,compilation!D$8) -> 9 | E17: =SUMIFS(T_Maint_Innofaso!G:G,T_Maint_Innofaso!B:B,A$11,T_Maint_Innofaso!C:C,B17,T_Maint_Innofaso!F:F,C17,T_Maint_Innofaso!D:D,E$8) -> 1 | F17: =SUMIFS(T_Maint_Innofaso!G:G,T_Maint_Innofaso!B:B,A$11,T_Maint_Innofaso!C:C,B17,T_Maint_Innofaso!F:F,C17,T_Maint_Innofaso!D:D,F$8) -> 3 | G17: =SUMIFS(T_Maint_Innofaso!G:G,T_Maint_Innofaso!B:B,A$11,T_Maint_Innofaso!C:C,B17,T_Maint_Innofaso!F:F,C17,T_Maint_Innofaso!D:D,G$8) -> 1 | H17: =SUMIFS(T_Maint_Innofaso!G:G,T_Maint_Innofaso!B:B,A$11,T_Maint_Innofaso!C:C,B17,T_Maint_Innofaso!F:F,C17,T_Maint_Innofaso!D:D,H$8) -> 1 | I17: =SUMIFS(T_Maint_Innofaso!G:G,T_Maint_Innofaso!B:B,A17,T_Maint_Innofaso!C:C,B17,T_Maint_Innofaso!F:F,C17,T_Maint_Innofaso!D:D,compilation!I8) -> 35.17 | J17: =SUMIFS(T_Maint_Innofaso!G:G,T_Maint_Innofaso!B:B,A$11,T_Maint_Innofaso!C:C,B17,T_Maint_Innofaso!F:F,C17,T_Maint_Innofaso!D:D,J$8) -> 7 | K17: =SUMIFS(T_Maint_Innofaso!G:G,T_Maint_Innofaso!B:B,A$11,T_Maint_Innofaso!C:C,B17,T_Maint_Innofaso!F:F,C17,T_Maint_Innofaso!D:D,K$8) -> 1 | L17: =SUMIFS(T_Maint_Innofaso!G:G,T_Maint_Innofaso!B:B,A$11,T_Maint_Innofaso!C:C,B17,T_Maint_Innofaso!F:F,C17,T_Maint_Innofaso!D:D,L$8) -> 0 | M17: =SUMIFS(T_Maint_Innofaso!G:G,T_Maint_Innofaso!B:B,A$11,T_Maint_Innofaso!C:C,B17,T_Maint_Innofaso!F:F,C17,T_Maint_Innofaso!D:D,M$8) -> 0 | N17: =SUMIFS(T_Maint_Innofaso!G:G,T_Maint_Innofaso!B:B,A$11,T_Maint_Innofaso!C:C,B17,T_Maint_Innofaso!F:F,C17,T_Maint_Innofaso!D:D,N$8) -> 0 | O17: =SUMIFS(T_Maint_Innofaso!G:G,T_Maint_Innofaso!B:B,A$11,T_Maint_Innofaso!C:C,B17,T_Maint_Innofaso!F:F,C17,T_Maint_Innofaso!D:D,O$8) -> 0 | P17: =SUM(D17:O17) -> 58.17 | Q17: =P17+P18 -> 97.97 | R17: incendie sur le compresseur 2 le 16/05/2025 et panne non resolu jusqu'au fin mai. Production sur L4 uniquement | W17: commande en cours pour nouveau compresseur | AB17: RT,LOG,RAF | AC17: 45838
C18: Corrective | D18: =SUMIFS(T_Maint_Innofaso!G:G,T_Maint_Innofaso!B:B,A$11,T_Maint_Innofaso!C:C,B17,T_Maint_Innofaso!F:F,C18,T_Maint_Innofaso!D:D,compilation!D$8) -> 2 | E18: =SUMIFS(T_Maint_Innofaso!G:G,T_Maint_Innofaso!B:B,A$11,T_Maint_Innofaso!C:C,B17,T_Maint_Innofaso!F:F,C18,T_Maint_Innofaso!D:D,E$8) -> 0 | F18: =SUMIFS(T_Maint_Innofaso!G:G,T_Maint_Innofaso!B:B,A$11,T_Maint_Innofaso!C:C,B17,T_Maint_Innofaso!F:F,C18,T_Maint_Innofaso!D:D,F$8) -> 8 | G18: =SUMIFS(T_Maint_Innofaso!G:G,T_Maint_Innofaso!B:B,A$11,T_Maint_Innofaso!C:C,B17,T_Maint_Innofaso!F:F,C16,T_Maint_Innofaso!D:D,G$8) -> 1.5 | H18: =SUMIFS(T_Maint_Innofaso!G:G,T_Maint_Innofaso!B:B,A$11,T_Maint_Innofaso!C:C,B17,T_Maint_Innofaso!F:F,C18,T_Maint_Innofaso!D:D,H$8) -> 0 | I18: =SUMIFS(T_Maint_Innofaso!G:G,T_Maint_Innofaso!B:B,A$11,T_Maint_Innofaso!C:C,B17,T_Maint_Innofaso!F:F,C18,T_Maint_Innofaso!D:D,I$8) -> 0 | J18: =SUMIFS(T_Maint_Innofaso!G:G,T_Maint_Innofaso!B:B,A$11,T_Maint_Innofaso!C:C,B17,T_Maint_Innofaso!F:F,C18,T_Maint_Innofaso!D:D,J$8) -> 21.8 | K18: =SUMIFS(T_Maint_Innofaso!G:G,T_Maint_Innofaso!B:B,A$11,T_Maint_Innofaso!C:C,B17,T_Maint_Innofaso!F:F,C18,T_Maint_Innofaso!D:D,K$8) -> 0 | L18: =SUMIFS(T_Maint_Innofaso!G:G,T_Maint_Innofaso!B:B,A$11,T_Maint_Innofaso!C:C,B17,T_Maint_Innofaso!F:F,C18,T_Maint_Innofaso!D:D,L$8) -> 6.5 | M18: =SUMIFS(T_Maint_Innofaso!G:G,T_Maint_Innofaso!B:B,A$11,T_Maint_Innofaso!C:C,B17,T_Maint_Innofaso!F:F,C18,T_Maint_Innofaso!D:D,M$8) -> 0 | N18: =SUMIFS(T_Maint_Innofaso!G:G,T_Maint_Innofaso!B:B,A$11,T_Maint_Innofaso!C:C,B17,T_Maint_Innofaso!F:F,C18,T_Maint_Innofaso!D:D,N$8) -> 0 | O18: =SUMIFS(T_Maint_Innofaso!G:G,T_Maint_Innofaso!B:B,A$11,T_Maint_Innofaso!C:C,B17,T_Maint_Innofaso!F:F,C18,T_Maint_Innofaso!D:D,O$8) -> 0 | P18: =SUM(D18:O18) -> 39.8
A19: 2025 | B19: Jun | C19: Preventive | D19: =SUMIFS(T_Maint_Innofaso!G:G,T_Maint_Innofaso!B:B,A$11,T_Maint_Innofaso!C:C,B19,T_Maint_Innofaso!F:F,C19,T_Maint_Innofaso!D:D,compilation!D$8) -> 2 | E19: =SUMIFS(T_Maint_Innofaso!G:G,T_Maint_Innofaso!B:B,A$11,T_Maint_Innofaso!C:C,B19,T_Maint_Innofaso!F:F,C19,T_Maint_Innofaso!D:D,E$8) -> 1 | F19: =SUMIFS(T_Maint_Innofaso!G:G,T_Maint_Innofaso!B:B,A$11,T_Maint_Innofaso!C:C,B19,T_Maint_Innofaso!F:F,C19,T_Maint_Innofaso!D:D,F$8) -> 3 | G19: =SUMIFS(T_Maint_Innofaso!G:G,T_Maint_Innofaso!B:B,A$11,T_Maint_Innofaso!C:C,B19,T_Maint_Innofaso!F:F,C19,T_Maint_Innofaso!D:D,G$8) -> 1 | H19: =SUMIFS(T_Maint_Innofaso!G:G,T_Maint_Innofaso!B:B,A$11,T_Maint_Innofaso!C:C,B19,T_Maint_Innofaso!F:F,C19,T_Maint_Innofaso!D:D,H$8) -> 1 | I19: =SUMIFS(T_Maint_Innofaso!G:G,T_Maint_Innofaso!B:B,A19,T_Maint_Innofaso!C:C,B19,T_Maint_Innofaso!F:F,C19,T_Maint_Innofaso!D:D,I8) -> 40.17 | J19: =SUMIFS(T_Maint_Innofaso!G:G,T_Maint_Innofaso!B:B,A$11,T_Maint_Innofaso!C:C,B19,T_Maint_Innofaso!F:F,C19,T_Maint_Innofaso!D:D,J$8) -> 7 | K19: =SUMIFS(T_Maint_Innofaso!G:G,T_Maint_Innofaso!B:B,A$11,T_Maint_Innofaso!C:C,B19,T_Maint_Innofaso!F:F,C19,T_Maint_Innofaso!D:D,K$8) -> 1 | L19: =SUMIFS(T_Maint_Innofaso!G:G,T_Maint_Innofaso!B:B,A$11,T_Maint_Innofaso!C:C,B19,T_Maint_Innofaso!F:F,C19,T_Maint_Innofaso!D:D,L$8) -> 0 | M19: =SUMIFS(T_Maint_Innofaso!G:G,T_Maint_Innofaso!B:B,A$11,T_Maint_Innofaso!C:C,B19,T_Maint_Innofaso!F:F,C19,T_Maint_Innofaso!D:D,M$8) -> 0 | N19: =SUMIFS(T_Maint_Innofaso!G:G,T_Maint_Innofaso!B:B,A$11,T_Maint_Innofaso!C:C,B19,T_Maint_Innofaso!F:F,C19,T_Maint_Innofaso!D:D,N$8) -> 0 | O19: =SUMIFS(T_Maint_Innofaso!G:G,T_Maint_Innofaso!B:B,A$11,T_Maint_Innofaso!C:C,B19,T_Maint_Innofaso!F:F,C19,T_Maint_Innofaso!D:D,O$8) -> 0 | P19: =SUM(D19:O19) -> 56.17 | Q19: =P19+P20 -> 82.12
C20: Corrective | D20: =SUMIFS(T_Maint_Innofaso!G:G,T_Maint_Innofaso!B:B,A$11,T_Maint_Innofaso!C:C,B19,T_Maint_Innofaso!F:F,C20,T_Maint_Innofaso!D:D,compilation!D$8) -> 3 | E20: =SUMIFS(T_Maint_Innofaso!G:G,T_Maint_Innofaso!B:B,A$11,T_Maint_Innofaso!C:C,B19,T_Maint_Innofaso!F:F,C20,T_Maint_Innofaso!D:D,E$8) -> 0 | F20: =SUMIFS(T_Maint_Innofaso!G:G,T_Maint_Innofaso!B:B,A$11,T_Maint_Innofaso!C:C,B19,T_Maint_Innofaso!F:F,C20,T_Maint_Innofaso!D:D,F$8) -> 1 | G20: =SUMIFS(T_Maint_Innofaso!G:G,T_Maint_Innofaso!B:B,A$11,T_Maint_Innofaso!C:C,B20,T_Maint_Innofaso!F:F,C20,T_Maint_Innofaso!D:D,G$8) -> 0 | H20: =SUMIFS(T_Maint_Innofaso!G:G,T_Maint_Innofaso!B:B,A$11,T_Maint_Innofaso!C:C,B19,T_Maint_Innofaso!F:F,C20,T_Maint_Innofaso!D:D,H$8) -> 0 | I20: =SUMIFS(T_Maint_Innofaso!G:G,T_Maint_Innofaso!B:B,A$11,T_Maint_Innofaso!C:C,B19,T_Maint_Innofaso!F:F,C20,T_Maint_Innofaso!D:D,I$8) -> 0 | J20: =SUMIFS(T_Maint_Innofaso!G:G,T_Maint_Innofaso!B:B,A$11,T_Maint_Innofaso!C:C,B19,T_Maint_Innofaso!F:F,C20,T_Maint_Innofaso!D:D,J$8) -> 11.25 | K20: =SUMIFS(T_Maint_Innofaso!G:G,T_Maint_Innofaso!B:B,A$11,T_Maint_Innofaso!C:C,B19,T_Maint_Innofaso!F:F,C20,T_Maint_Innofaso!D:D,K$8) -> 10.7 | L20: =SUMIFS(T_Maint_Innofaso!G:G,T_Maint_Innofaso!B:B,A$11,T_Maint_Innofaso!C:C,B19,T_Maint_Innofaso!F:F,C20,T_Maint_Innofaso!D:D,L$8) -> 0 | M20: =SUMIFS(T_Maint_Innofaso!G:G,T_Maint_Innofaso!B:B,A$11,T_Maint_Innofaso!C:C,B19,T_Maint_Innofaso!F:F,C20,T_Maint_Innofaso!D:D,M$8) -> 0 | N20: =SUMIFS(T_Maint_Innofaso!G:G,T_Maint_Innofaso!B:B,A$11,T_Maint_Innofaso!C:C,B19,T_Maint_Innofaso!F:F,C20,T_Maint_Innofaso!D:D,N$8) -> 0 | O20: =SUMIFS(T_Maint_Innofaso!G:G,T_Maint_Innofaso!B:B,A$11,T_Maint_Innofaso!C:C,B19,T_Maint_Innofaso!F:F,C20,T_Maint_Innofaso!D:D,O$8) -> 0 | P20: =SUM(D20:O20) -> 25.95
A21: 2025 | B21: Jul | C21: Preventive | D21: =SUMIFS(T_Maint_Innofaso!G:G,T_Maint_Innofaso!B:B,A$11,T_Maint_Innofaso!C:C,B21,T_Maint_Innofaso!F:F,C21,T_Maint_Innofaso!D:D,compilation!D$8) -> 33 | E21: =SUMIFS(T_Maint_Innofaso!G:G,T_Maint_Innofaso!B:B,A$11,T_Maint_Innofaso!C:C,B21,T_Maint_Innofaso!F:F,C21,T_Maint_Innofaso!D:D,compilation!E$8) -> 1 | F21: =SUMIFS(T_Maint_Innofaso!G:G,T_Maint_Innofaso!B:B,A$11,T_Maint_Innofaso!C:C,B21,T_Maint_Innofaso!F:F,C21,T_Maint_Innofaso!D:D,F$8) -> 3 | G21: =SUMIFS(T_Maint_Innofaso!G:G,T_Maint_Innofaso!B:B,A$11,T_Maint_Innofaso!C:C,B21,T_Maint_Innofaso!F:F,C21,T_Maint_Innofaso!D:D,G$8) -> 1 | H21: =SUMIFS(T_Maint_Innofaso!G:G,T_Maint_Innofaso!B:B,A$11,T_Maint_Innofaso!C:C,B21,T_Maint_Innofaso!F:F,C21,T_Maint_Innofaso!D:D,H$8) -> 1 | I21: =SUMIFS(T_Maint_Innofaso!G:G,T_Maint_Innofaso!B:B,A$11,T_Maint_Innofaso!C:C,B21,T_Maint_Innofaso!F:F,C21,T_Maint_Innofaso!D:D,I$8) -> 31.67 | J21: =SUMIFS(T_Maint_Innofaso!G:G,T_Maint_Innofaso!B:B,A$11,T_Maint_Innofaso!C:C,B21,T_Maint_Innofaso!F:F,C21,T_Maint_Innofaso!D:D,J$8) -> 7 | K21: =SUMIFS(T_Maint_Innofaso!G:G,T_Maint_Innofaso!B:B,A$11,T_Maint_Innofaso!C:C,B21,T_Maint_Innofaso!F:F,C21,T_Maint_Innofaso!D:D,K$8) -> 1 | L21: =SUMIFS(T_Maint_Innofaso!G:G,T_Maint_Innofaso!B:B,A$11,T_Maint_Innofaso!C:C,B21,T_Maint_Innofaso!F:F,C21,T_Maint_Innofaso!D:D,L$8) -> 0 | M21: =SUMIFS(T_Maint_Innofaso!G:G,T_Maint_Innofaso!B:B,A$11,T_Maint_Innofaso!C:C,B21,T_Maint_Innofaso!F:F,C21,T_Maint_Innofaso!D:D,M$8) -> 0 | N21: =SUMIFS(T_Maint_Innofaso!G:G,T_Maint_Innofaso!B:B,A$11,T_Maint_Innofaso!C:C,B21,T_Maint_Innofaso!F:F,C21,T_Maint_Innofaso!D:D,N$8) -> 0 | O21: =SUMIFS(T_Maint_Innofaso!G:G,T_Maint_Innofaso!B:B,A$11,T_Maint_Innofaso!C:C,B21,T_Maint_Innofaso!F:F,C21,T_Maint_Innofaso!D:D,O$8) -> 0 | P21: =SUM(D21:O21) -> 78.67 | Q21: =P21+P22 -> 125.02 | R21: incendie sur le compresseur 2 le 16/05/2025 et panne non resolu jusqu'au fin mai. Production sur L4 uniquement | W21: installation du compresseur3 du 22 au 25 | AB21: RT/CM/AM | AC21: CLOS
C22: Corrective | D22: =SUMIFS(T_Maint_Innofaso!G:G,T_Maint_Innofaso!B:B,A$11,T_Maint_Innofaso!C:C,B21,T_Maint_Innofaso!F:F,C22,T_Maint_Innofaso!D:D,compilation!D$8) -> 0 | E22: =SUMIFS(T_Maint_Innofaso!G:G,T_Maint_Innofaso!B:B,A$11,T_Maint_Innofaso!C:C,B21,T_Maint_Innofaso!F:F,C22,T_Maint_Innofaso!D:D,E$8) -> 0 | F22: =SUMIFS(T_Maint_Innofaso!G:G,T_Maint_Innofaso!B:B,A$11,T_Maint_Innofaso!C:C,B21,T_Maint_Innofaso!F:F,C22,T_Maint_Innofaso!D:D,F$8) -> 4.7 | G22: =SUMIFS(T_Maint_Innofaso!G:G,T_Maint_Innofaso!B:B,A$11,T_Maint_Innofaso!C:C,B21,T_Maint_Innofaso!F:F,C22,T_Maint_Innofaso!D:D,G$8) -> 0 | H22: =SUMIFS(T_Maint_Innofaso!G:G,T_Maint_Innofaso!B:B,A$11,T_Maint_Innofaso!C:C,B21,T_Maint_Innofaso!F:F,C22,T_Maint_Innofaso!D:D,H$8) -> 0 | I22: =SUMIFS(T_Maint_Innofaso!G:G,T_Maint_Innofaso!B:B,A$11,T_Maint_Innofaso!C:C,B21,T_Maint_Innofaso!F:F,C22,T_Maint_Innofaso!D:D,I$8) -> 3.4 | J22: =SUMIFS(T_Maint_Innofaso!G:G,T_Maint_Innofaso!B:B,A$11,T_Maint_Innofaso!C:C,B21,T_Maint_Innofaso!F:F,C22,T_Maint_Innofaso!D:D,J$8) -> 23.8 | K22: =SUMIFS(T_Maint_Innofaso!G:G,T_Maint_Innofaso!B:B,A$11,T_Maint_Innofaso!C:C,B21,T_Maint_Innofaso!F:F,C22,T_Maint_Innofaso!D:D,K$8) -> 5 | L22: =SUMIFS(T_Maint_Innofaso!G:G,T_Maint_Innofaso!B:B,A$11,T_Maint_Innofaso!C:C,B21,T_Maint_Innofaso!F:F,C22,T_Maint_Innofaso!D:D,L$8) -> 0.95 | M22: =SUMIFS(T_Maint_Innofaso!G:G,T_Maint_Innofaso!B:B,A$11,T_Maint_Innofaso!C:C,B21,T_Maint_Innofaso!F:F,C22,T_Maint_Innofaso!D:D,M$8) -> 8.5 | N22: =SUMIFS(T_Maint_Innofaso!G:G,T_Maint_Innofaso!B:B,A$11,T_Maint_Innofaso!C:C,B21,T_Maint_Innofaso!F:F,C22,T_Maint_Innofaso!D:D,N$8) -> 0 | O22: =SUMIFS(T_Maint_Innofaso!G:G,T_Maint_Innofaso!B:B,A$11,T_Maint_Innofaso!C:C,B21,T_Maint_Innofaso!F:F,C22,T_Maint_Innofaso!D:D,O$8) -> 0 | P22: =SUM(D22:O22) -> 46.35
A23: 2025 | B23: Aug | C23: Preventive | D23: =SUMIFS(T_Maint_Innofaso!G:G,T_Maint_Innofaso!B:B,A$11,T_Maint_Innofaso!C:C,B23,T_Maint_Innofaso!F:F,C23,T_Maint_Innofaso!D:D,compilation!D$8) -> 2 | E23: =SUMIFS(T_Maint_Innofaso!G:G,T_Maint_Innofaso!B:B,A$11,T_Maint_Innofaso!C:C,B23,T_Maint_Innofaso!F:F,C23,T_Maint_Innofaso!D:D,E$8) -> 1 | F23: =SUMIFS(T_Maint_Innofaso!G:G,T_Maint_Innofaso!B:B,A$11,T_Maint_Innofaso!C:C,B23,T_Maint_Innofaso!F:F,C23,T_Maint_Innofaso!D:D,F$8) -> 3 | G23: =SUMIFS(T_Maint_Innofaso!G:G,T_Maint_Innofaso!B:B,A$11,T_Maint_Innofaso!C:C,B23,T_Maint_Innofaso!F:F,C23,T_Maint_Innofaso!D:D,G$8) -> 1 | H23: =SUMIFS(T_Maint_Innofaso!G:G,T_Maint_Innofaso!B:B,A$11,T_Maint_Innofaso!C:C,B23,T_Maint_Innofaso!F:F,C23,T_Maint_Innofaso!D:D,H$8) -> 1 | I23: =SUMIFS(T_Maint_Innofaso!G:G,T_Maint_Innofaso!B:B,A$11,T_Maint_Innofaso!C:C,B23,T_Maint_Innofaso!F:F,C23,T_Maint_Innofaso!D:D,I$8) -> 31.67 | J23: =SUMIFS(T_Maint_Innofaso!G:G,T_Maint_Innofaso!B:B,A$11,T_Maint_Innofaso!C:C,B23,T_Maint_Innofaso!F:F,C23,T_Maint_Innofaso!D:D,J$8) -> 7 | K23: =SUMIFS(T_Maint_Innofaso!G:G,T_Maint_Innofaso!B:B,A$11,T_Maint_Innofaso!C:C,B23,T_Maint_Innofaso!F:F,C23,T_Maint_Innofaso!D:D,K$8) -> 1 | L23: =SUMIFS(T_Maint_Innofaso!G:G,T_Maint_Innofaso!B:B,A$11,T_Maint_Innofaso!C:C,B23,T_Maint_Innofaso!F:F,C23,T_Maint_Innofaso!D:D,L$8) -> 4 | M23: =SUMIFS(T_Maint_Innofaso!G:G,T_Maint_Innofaso!B:B,A$11,T_Maint_Innofaso!C:C,B23,T_Maint_Innofaso!F:F,C23,T_Maint_Innofaso!D:D,M$8) -> 0 | N23: =SUMIFS(T_Maint_Innofaso!G:G,T_Maint_Innofaso!B:B,A$11,T_Maint_Innofaso!C:C,B23,T_Maint_Innofaso!F:F,C23,T_Maint_Innofaso!D:D,N$8) -> 0 | O23: =SUMIFS(T_Maint_Innofaso!G:G,T_Maint_Innofaso!B:B,A$11,T_Maint_Innofaso!C:C,B23,T_Maint_Innofaso!F:F,C23,T_Maint_Innofaso!D:D,O$8) -> 0 | P23: =SUM(D23:O23) -> 51.67 | Q23: =P23+P24 -> 94.72 | R23: Beaucoup de panne avec L4. problème de lames qui cassent | W23: commande de lame en cours | AB23: 45900 | AC23: clos
C24: Corrective | D24: =SUMIFS(T_Maint_Innofaso!G:G,T_Maint_Innofaso!B:B,A$11,T_Maint_Innofaso!C:C,B23,T_Maint_Innofaso!F:F,C24,T_Maint_Innofaso!D:D,compilation!D$8) -> 0 | E24: =SUMIFS(T_Maint_Innofaso!G:G,T_Maint_Innofaso!B:B,A$11,T_Maint_Innofaso!C:C,B23,T_Maint_Innofaso!F:F,C24,T_Maint_Innofaso!D:D,E$8) -> 0 | F24: =SUMIFS(T_Maint_Innofaso!G:G,T_Maint_Innofaso!B:B,A$11,T_Maint_Innofaso!C:C,B23,T_Maint_Innofaso!F:F,C24,T_Maint_Innofaso!D:D,F$8) -> 1.5 | G24: =SUMIFS(T_Maint_Innofaso!G:G,T_Maint_Innofaso!B:B,A$11,T_Maint_Innofaso!C:C,B23,T_Maint_Innofaso!F:F,C24,T_Maint_Innofaso!D:D,G$8) -> 5.9 | H24: =SUMIFS(T_Maint_Innofaso!G:G,T_Maint_Innofaso!B:B,A$11,T_Maint_Innofaso!C:C,B23,T_Maint_Innofaso!F:F,C24,T_Maint_Innofaso!D:D,H$8) -> 0 | I24: =SUMIFS(T_Maint_Innofaso!G:G,T_Maint_Innofaso!B:B,A$11,T_Maint_Innofaso!C:C,B23,T_Maint_Innofaso!F:F,C24,T_Maint_Innofaso!D:D,I$8) -> 1 | J24: =SUMIFS(T_Maint_Innofaso!G:G,T_Maint_Innofaso!B:B,A$11,T_Maint_Innofaso!C:C,B23,T_Maint_Innofaso!F:F,C24,T_Maint_Innofaso!D:D,J$8) -> 33.65 | K24: =SUMIFS(T_Maint_Innofaso!G:G,T_Maint_Innofaso!B:B,A$11,T_Maint_Innofaso!C:C,B23,T_Maint_Innofaso!F:F,C24,T_Maint_Innofaso!D:D,K$8) -> 1 | L24: =SUMIFS(T_Maint_Innofaso!G:G,T_Maint_Innofaso!B:B,A$11,T_Maint_Innofaso!C:C,B23,T_Maint_Innofaso!F:F,C24,T_Maint_Innofaso!D:D,L$8) -> 0 | M24: =SUMIFS(T_Maint_Innofaso!G:G,T_Maint_Innofaso!B:B,A$11,T_Maint_Innofaso!C:C,B23,T_Maint_Innofaso!F:F,C24,T_Maint_Innofaso!D:D,M$8) -> 0 | N24: =SUMIFS(T_Maint_Innofaso!G:G,T_Maint_Innofaso!B:B,A$11,T_Maint_Innofaso!C:C,B23,T_Maint_Innofaso!F:F,C24,T_Maint_Innofaso!D:D,N$8) -> 0 | O24: =SUMIFS(T_Maint_Innofaso!G:G,T_Maint_Innofaso!B:B,A$11,T_Maint_Innofaso!C:C,B23,T_Maint_Innofaso!F:F,C24,T_Maint_Innofaso!D:D,O$8) -> 0 | P24: =SUM(D24:O24) -> 43.05
A25: 2025 | B25: Sep | C25: Preventive | D25: =SUMIFS(T_Maint_Innofaso!G:G,T_Maint_Innofaso!B:B,A$11,T_Maint_Innofaso!C:C,B25,T_Maint_Innofaso!F:F,C25,T_Maint_Innofaso!D:D,compilation!D$8) -> 2 | E25: =SUMIFS(T_Maint_Innofaso!G:G,T_Maint_Innofaso!B:B,A$11,T_Maint_Innofaso!C:C,B25,T_Maint_Innofaso!F:F,C25,T_Maint_Innofaso!D:D,E$8) -> 1 | F25: =SUMIFS(T_Maint_Innofaso!G:G,T_Maint_Innofaso!B:B,A$11,T_Maint_Innofaso!C:C,B25,T_Maint_Innofaso!F:F,C25,T_Maint_Innofaso!D:D,F$8) -> 28.5 | G25: =SUMIFS(T_Maint_Innofaso!G:G,T_Maint_Innofaso!B:B,A$11,T_Maint_Innofaso!C:C,B25,T_Maint_Innofaso!F:F,C25,T_Maint_Innofaso!D:D,G$8) -> 1 | H25: =SUMIFS(T_Maint_Innofaso!G:G,T_Maint_Innofaso!B:B,A$11,T_Maint_Innofaso!C:C,B25,T_Maint_Innofaso!F:F,C25,T_Maint_Innofaso!D:D,H$8) -> 1.5 | I25: =SUMIFS(T_Maint_Innofaso!G:G,T_Maint_Innofaso!B:B,A$11,T_Maint_Innofaso!C:C,B25,T_Maint_Innofaso!F:F,C25,T_Maint_Innofaso!D:D,I$8) -> 43.67 | J25: =SUMIFS(T_Maint_Innofaso!G:G,T_Maint_Innofaso!B:B,A$11,T_Maint_Innofaso!C:C,B25,T_Maint_Innofaso!F:F,C25,T_Maint_Innofaso!D:D,J$8) -> 25 | K25: =SUMIFS(T_Maint_Innofaso!G:G,T_Maint_Innofaso!B:B,A$11,T_Maint_Innofaso!C:C,B25,T_Maint_Innofaso!F:F,C25,T_Maint_Innofaso!D:D,K$8) -> 1.5 | L25: =SUMIFS(T_Maint_Innofaso!G:G,T_Maint_Innofaso!B:B,A$11,T_Maint_Innofaso!C:C,B25,T_Maint_Innofaso!F:F,C25,T_Maint_Innofaso!D:D,L$8) -> 4 | M25: =SUMIFS(T_Maint_Innofaso!G:G,T_Maint_Innofaso!B:B,A$11,T_Maint_Innofaso!C:C,B25,T_Maint_Innofaso!F:F,C25,T_Maint_Innofaso!D:D,M$8) -> 0 | N25: =SUMIFS(T_Maint_Innofaso!G:G,T_Maint_Innofaso!B:B,A$11,T_Maint_Innofaso!C:C,B25,T_Maint_Innofaso!F:F,C25,T_Maint_Innofaso!D:D,N$8) -> 0 | O25: =SUMIFS(T_Maint_Innofaso!G:G,T_Maint_Innofaso!B:B,A$11,T_Maint_Innofaso!C:C,B25,T_Maint_Innofaso!F:F,C25,T_Maint_Innofaso!D:D,O$8) -> 0 | P25: =SUM(D25:O25) -> 108.17 | Q25: =P25+P26 -> 129.77 | R25: changement de produit (ENB+)
C26: Corrective | D26: =SUMIFS(T_Maint_Innofaso!G:G,T_Maint_Innofaso!B:B,A$11,T_Maint_Innofaso!C:C,B25,T_Maint_Innofaso!F:F,C26,T_Maint_Innofaso!D:D,compilation!D$8) -> 1 | E26: =SUMIFS(T_Maint_Innofaso!G:G,T_Maint_Innofaso!B:B,A$11,T_Maint_Innofaso!C:C,B25,T_Maint_Innofaso!F:F,C26,T_Maint_Innofaso!D:D,E$8) -> 0 | F26: =SUMIFS(T_Maint_Innofaso!G:G,T_Maint_Innofaso!B:B,A$11,T_Maint_Innofaso!C:C,B25,T_Maint_Innofaso!F:F,C26,T_Maint_Innofaso!D:D,F$8) -> 4 | G26: =SUMIFS(T_Maint_Innofaso!G:G,T_Maint_Innofaso!B:B,A$11,T_Maint_Innofaso!C:C,B25,T_Maint_Innofaso!F:F,C26,T_Maint_Innofaso!D:D,G$8) -> 1 | H26: =SUMIFS(T_Maint_Innofaso!G:G,T_Maint_Innofaso!B:B,A$11,T_Maint_Innofaso!C:C,B25,T_Maint_Innofaso!F:F,C26,T_Maint_Innofaso!D:D,H$8) -> 0 | I26: =SUMIFS(T_Maint_Innofaso!G:G,T_Maint_Innofaso!B:B,A$11,T_Maint_Innofaso!C:C,B25,T_Maint_Innofaso!F:F,C26,T_Maint_Innofaso!D:D,I$8) -> 0 | J26: =SUMIFS(T_Maint_Innofaso!G:G,T_Maint_Innofaso!B:B,A$11,T_Maint_Innofaso!C:C,B25,T_Maint_Innofaso!F:F,C26,T_Maint_Innofaso!D:D,J$8) -> 6.85 | K26: =SUMIFS(T_Maint_Innofaso!G:G,T_Maint_Innofaso!B:B,A$11,T_Maint_Innofaso!C:C,B25,T_Maint_Innofaso!F:F,C26,T_Maint_Innofaso!D:D,K$8) -> 1 | L26: =SUMIFS(T_Maint_Innofaso!G:G,T_Maint_Innofaso!B:B,A$11,T_Maint_Innofaso!C:C,B25,T_Maint_Innofaso!F:F,C26,T_Maint_Innofaso!D:D,L$8) -> 5.75 | M26: =SUMIFS(T_Maint_Innofaso!G:G,T_Maint_Innofaso!B:B,A$11,T_Maint_Innofaso!C:C,B25,T_Maint_Innofaso!F:F,C26,T_Maint_Innofaso!D:D,M$8) -> 0 | N26: =SUMIFS(T_Maint_Innofaso!G:G,T_Maint_Innofaso!B:B,A$11,T_Maint_Innofaso!C:C,B25,T_Maint_Innofaso!F:F,C26,T_Maint_Innofaso!D:D,N$8) -> 0 | O26: =SUMIFS(T_Maint_Innofaso!G:G,T_Maint_Innofaso!B:B,A$11,T_Maint_Innofaso!C:C,B25,T_Maint_Innofaso!F:F,C26,T_Maint_Innofaso!D:D,O$8) -> 2 | P26: =SUM(D26:O26) -> 21.6
A27: 2025 | B27: Oct | C27: Preventive | D27: =SUMIFS(T_Maint_Innofaso!G:G,T_Maint_Innofaso!B:B,A$11,T_Maint_Innofaso!C:C,B27,T_Maint_Innofaso!F:F,C27,T_Maint_Innofaso!D:D,compilation!D$8) -> 2 | E27: =SUMIFS(T_Maint_Innofaso!G:G,T_Maint_Innofaso!B:B,A$11,T_Maint_Innofaso!C:C,B27,T_Maint_Innofaso!F:F,C27,T_Maint_Innofaso!D:D,E$8) -> 1 | F27: =SUMIFS(T_Maint_Innofaso!G:G,T_Maint_Innofaso!B:B,A$11,T_Maint_Innofaso!C:C,B27,T_Maint_Innofaso!F:F,C27,T_Maint_Innofaso!D:D,F$8) -> 25 | G27: =SUMIFS(T_Maint_Innofaso!G:G,T_Maint_Innofaso!B:B,A$11,T_Maint_Innofaso!C:C,B27,T_Maint_Innofaso!F:F,C27,T_Maint_Innofaso!D:D,G$8) -> 1 | H27: =SUMIFS(T_Maint_Innofaso!G:G,T_Maint_Innofaso!B:B,A$11,T_Maint_Innofaso!C:C,B27,T_Maint_Innofaso!F:F,C27,T_Maint_Innofaso!D:D,H$8) -> 1 | I27: =SUMIFS(T_Maint_Innofaso!G:G,T_Maint_Innofaso!B:B,A$11,T_Maint_Innofaso!C:C,B27,T_Maint_Innofaso!F:F,C27,T_Maint_Innofaso!D:D,I$8) -> 33.67 | J27: =SUMIFS(T_Maint_Innofaso!G:G,T_Maint_Innofaso!B:B,A$11,T_Maint_Innofaso!C:C,B27,T_Maint_Innofaso!F:F,C27,T_Maint_Innofaso!D:D,J$8) -> 23 | K27: =SUMIFS(T_Maint_Innofaso!G:G,T_Maint_Innofaso!B:B,A$11,T_Maint_Innofaso!C:C,B27,T_Maint_Innofaso!F:F,C27,T_Maint_Innofaso!D:D,K$8) -> 1 | L27: =SUMIFS(T_Maint_Innofaso!G:G,T_Maint_Innofaso!B:B,A$11,T_Maint_Innofaso!C:C,B27,T_Maint_Innofaso!F:F,C27,T_Maint_Innofaso!D:D,L$8) -> 4 | M27: =SUMIFS(T_Maint_Innofaso!G:G,T_Maint_Innofaso!B:B,A$11,T_Maint_Innofaso!C:C,B27,T_Maint_Innofaso!F:F,C27,T_Maint_Innofaso!D:D,M$8) -> 0 | N27: =SUMIFS(T_Maint_Innofaso!G:G,T_Maint_Innofaso!B:B,A$11,T_Maint_Innofaso!C:C,B27,T_Maint_Innofaso!F:F,C27,T_Maint_Innofaso!D:D,N$8) -> 0 | O27: =SUMIFS(T_Maint_Innofaso!G:G,T_Maint_Innofaso!B:B,A$11,T_Maint_Innofaso!C:C,B27,T_Maint_Innofaso!F:F,C27,T_Maint_Innofaso!D:D,O$8) -> 0 | P27: =SUM(D27:O27) -> 91.67 | Q27: =P27+P28 -> 126.32 | R27: bonne production constatée sans problèmes majeures
C28: Corrective | D28: =SUMIFS(T_Maint_Innofaso!G:G,T_Maint_Innofaso!B:B,A$11,T_Maint_Innofaso!C:C,B27,T_Maint_Innofaso!F:F,C28,T_Maint_Innofaso!D:D,compilation!D$8) -> 0.25 | E28: =SUMIFS(T_Maint_Innofaso!G:G,T_Maint_Innofaso!B:B,A$11,T_Maint_Innofaso!C:C,B27,T_Maint_Innofaso!F:F,C28,T_Maint_Innofaso!D:D,E$8) -> 0 | F28: =SUMIFS(T_Maint_Innofaso!G:G,T_Maint_Innofaso!B:B,A$11,T_Maint_Innofaso!C:C,B27,T_Maint_Innofaso!F:F,C28,T_Maint_Innofaso!D:D,F$8) -> 0 | G28: =SUMIFS(T_Maint_Innofaso!G:G,T_Maint_Innofaso!B:B,A$11,T_Maint_Innofaso!C:C,B27,T_Maint_Innofaso!F:F,C28,T_Maint_Innofaso!D:D,G$8) -> 0 | H28: =SUMIFS(T_Maint_Innofaso!G:G,T_Maint_Innofaso!B:B,A$11,T_Maint_Innofaso!C:C,B27,T_Maint_Innofaso!F:F,C28,T_Maint_Innofaso!D:D,H$8) -> 0 | I28: =SUMIFS(T_Maint_Innofaso!G:G,T_Maint_Innofaso!B:B,A$11,T_Maint_Innofaso!C:C,B27,T_Maint_Innofaso!F:F,C28,T_Maint_Innofaso!D:D,I$8) -> 7.5 | J28: =SUMIFS(T_Maint_Innofaso!G:G,T_Maint_Innofaso!B:B,A27,T_Maint_Innofaso!C:C,B27,T_Maint_Innofaso!F:F,C28,T_Maint_Innofaso!D:D,J8) -> 16.9 | K28: =SUMIFS(T_Maint_Innofaso!G:G,T_Maint_Innofaso!B:B,A$11,T_Maint_Innofaso!C:C,B27,T_Maint_Innofaso!F:F,C28,T_Maint_Innofaso!D:D,K$8) -> 7.5 | L28: =SUMIFS(T_Maint_Innofaso!G:G,T_Maint_Innofaso!B:B,A$11,T_Maint_Innofaso!C:C,B27,T_Maint_Innofaso!F:F,C28,T_Maint_Innofaso!D:D,L$8) -> 2.5 | M28: =SUMIFS(T_Maint_Innofaso!G:G,T_Maint_Innofaso!B:B,A$11,T_Maint_Innofaso!C:C,B27,T_Maint_Innofaso!F:F,C28,T_Maint_Innofaso!D:D,M$8) -> 0 | N28: =SUMIFS(T_Maint_Innofaso!G:G,T_Maint_Innofaso!B:B,A$11,T_Maint_Innofaso!C:C,B27,T_Maint_Innofaso!F:F,C28,T_Maint_Innofaso!D:D,N$8) -> 0 | O28: =SUMIFS(T_Maint_Innofaso!G:G,T_Maint_Innofaso!B:B,A$11,T_Maint_Innofaso!C:C,B27,T_Maint_Innofaso!F:F,C28,T_Maint_Innofaso!D:D,O$8) -> 0 | P28: =SUM(D28:O28) -> 34.65
A29: 2025 | B29: Nov | C29: Preventive | D29: =SUMIFS(T_Maint_Innofaso!G:G,T_Maint_Innofaso!B:B,A$11,T_Maint_Innofaso!C:C,B29,T_Maint_Innofaso!F:F,C29,T_Maint_Innofaso!D:D,compilation!D$8) -> 2 | E29: =SUMIFS(T_Maint_Innofaso!G:G,T_Maint_Innofaso!B:B,A$11,T_Maint_Innofaso!C:C,B29,T_Maint_Innofaso!F:F,C29,T_Maint_Innofaso!D:D,E$8) -> 1 | F29: =SUMIFS(T_Maint_Innofaso!G:G,T_Maint_Innofaso!B:B,A$11,T_Maint_Innofaso!C:C,B29,T_Maint_Innofaso!F:F,C29,T_Maint_Innofaso!D:D,F$8) -> 25 | G29: =SUMIFS(T_Maint_Innofaso!G:G,T_Maint_Innofaso!B:B,A$11,T_Maint_Innofaso!C:C,B29,T_Maint_Innofaso!F:F,C29,T_Maint_Innofaso!D:D,G$8) -> 1 | H29: =SUMIFS(T_Maint_Innofaso!G:G,T_Maint_Innofaso!B:B,A$11,T_Maint_Innofaso!C:C,B29,T_Maint_Innofaso!F:F,C29,T_Maint_Innofaso!D:D,H$8) -> 1 | I29: =SUMIFS(T_Maint_Innofaso!G:G,T_Maint_Innofaso!B:B,A$11,T_Maint_Innofaso!C:C,B29,T_Maint_Innofaso!F:F,C29,T_Maint_Innofaso!D:D,I$8) -> 33.67 | J29: =SUMIFS(T_Maint_Innofaso!G:G,T_Maint_Innofaso!B:B,A$11,T_Maint_Innofaso!C:C,B29,T_Maint_Innofaso!F:F,C29,T_Maint_Innofaso!D:D,J$8) -> 23 | K29: =SUMIFS(T_Maint_Innofaso!G:G,T_Maint_Innofaso!B:B,A$11,T_Maint_Innofaso!C:C,B29,T_Maint_Innofaso!F:F,C29,T_Maint_Innofaso!D:D,K$8) -> 1 | L29: =SUMIFS(T_Maint_Innofaso!G:G,T_Maint_Innofaso!B:B,A$11,T_Maint_Innofaso!C:C,B29,T_Maint_Innofaso!F:F,C29,T_Maint_Innofaso!D:D,L$8) -> 4 | M29: =SUMIFS(T_Maint_Innofaso!G:G,T_Maint_Innofaso!B:B,A$11,T_Maint_Innofaso!C:C,B29,T_Maint_Innofaso!F:F,C29,T_Maint_Innofaso!D:D,M$8) -> 0 | N29: =SUMIFS(T_Maint_Innofaso!G:G,T_Maint_Innofaso!B:B,A$11,T_Maint_Innofaso!C:C,B29,T_Maint_Innofaso!F:F,C29,T_Maint_Innofaso!D:D,N$8) -> 0 | O29: =SUMIFS(T_Maint_Innofaso!G:G,T_Maint_Innofaso!B:B,A$11,T_Maint_Innofaso!C:C,B29,T_Maint_Innofaso!F:F,C29,T_Maint_Innofaso!D:D,O$8) -> 0 | P29: =SUM(D29:O29) -> 91.67 | Q29: =P29+P30 -> 130.52 | R29: beaucoup de difficultés en thermisation avec des bouchons et le moteur de la chaudière HS | W29: Moteur rebobiné et une commande lancée pour un remplacement et stock | AC29: 46112
C30: Corrective | D30: =SUMIFS(T_Maint_Innofaso!G:G,T_Maint_Innofaso!B:B,compilation!A29,T_Maint_Innofaso!C:C,compilation!B29,T_Maint_Innofaso!D:D,compilation!D8,T_Maint_Innofaso!F:F,compilation!C30) -> 0 | E30: =SUMIFS(T_Maint_Innofaso!G:G,T_Maint_Innofaso!B:B,compilation!A29,T_Maint_Innofaso!C:C,compilation!B29,T_Maint_Innofaso!D:D,E8,T_Maint_Innofaso!F:F,compilation!C30) -> 0 | F30: =SUMIFS(T_Maint_Innofaso!G:G,T_Maint_Innofaso!B:B,compilation!A29,T_Maint_Innofaso!C:C,compilation!B29,T_Maint_Innofaso!D:D,F8,T_Maint_Innofaso!F:F,compilation!C30) -> 5.15 | G30: =SUMIFS(T_Maint_Innofaso!G:G,T_Maint_Innofaso!B:B,compilation!A29,T_Maint_Innofaso!C:C,compilation!B29,T_Maint_Innofaso!D:D,G8,T_Maint_Innofaso!F:F,compilation!C30) -> 1.8 | H30: =SUMIFS(T_Maint_Innofaso!G:G,T_Maint_Innofaso!B:B,compilation!A29,T_Maint_Innofaso!C:C,compilation!B29,T_Maint_Innofaso!D:D,H8,T_Maint_Innofaso!F:F,compilation!C30) -> 0 | I30: =SUMIFS(T_Maint_Innofaso!G:G,T_Maint_Innofaso!B:B,compilation!A29,T_Maint_Innofaso!C:C,compilation!B29,T_Maint_Innofaso!D:D,I8,T_Maint_Innofaso!F:F,compilation!C30) -> 3.65 | J30: =SUMIFS(T_Maint_Innofaso!G:G,T_Maint_Innofaso!B:B,compilation!A29,T_Maint_Innofaso!C:C,compilation!B29,T_Maint_Innofaso!D:D,J8,T_Maint_Innofaso!F:F,compilation!C30) -> 15.25 | K30: =SUMIFS(T_Maint_Innofaso!G:G,T_Maint_Innofaso!B:B,compilation!A29,T_Maint_Innofaso!C:C,compilation!B29,T_Maint_Innofaso!D:D,K8,T_Maint_Innofaso!F:F,compilation!C30) -> 12 | L30: =SUMIFS(T_Maint_Innofaso!G:G,T_Maint_Innofaso!B:B,compilation!A29,T_Maint_Innofaso!C:C,compilation!B29,T_Maint_Innofaso!D:D,L8,T_Maint_Innofaso!F:F,compilation!C30) -> 1 | M30: =SUMIFS(T_Maint_Innofaso!G:G,T_Maint_Innofaso!B:B,compilation!A29,T_Maint_Innofaso!C:C,compilation!B29,T_Maint_Innofaso!D:D,M8,T_Maint_Innofaso!F:F,compilation!C30) -> 0 | N30: =SUMIFS(T_Maint_Innofaso!G:G,T_Maint_Innofaso!B:B,compilation!A29,T_Maint_Innofaso!C:C,compilation!B29,T_Maint_Innofaso!D:D,N8,T_Maint_Innofaso!F:F,compilation!C30) -> 0 | O30: =SUMIFS(T_Maint_Innofaso!G:G,T_Maint_Innofaso!B:B,compilation!A29,T_Maint_Innofaso!C:C,compilation!B29,T_Maint_Innofaso!D:D,O8,T_Maint_Innofaso!F:F,compilation!C30) -> 0 | P30: =SUM(D30:O30) -> 38.85
A31: 2025 | B31: Dec | C31: Preventive | D31: =SUMIFS(T_Maint_Innofaso_2[Number of hours],T_Maint_Innofaso_2[Année],A31,T_Maint_Innofaso_2[Mois],B31,T_Maint_Innofaso_2[Maintenance Type],C31,T_Maint_Innofaso_2[Equipment],D8) -> 2 | E31: =SUMIFS(T_Maint_Innofaso_2[Number of hours],T_Maint_Innofaso_2[Année],A31,T_Maint_Innofaso_2[Mois],B31,T_Maint_Innofaso_2[Maintenance Type],C31,T_Maint_Innofaso_2[Equipment],compilation!E8) -> 1 | F31: =SUMIFS(T_Maint_Innofaso_2[Number of hours],T_Maint_Innofaso_2[Année],A31,T_Maint_Innofaso_2[Mois],B31,T_Maint_Innofaso_2[Maintenance Type],C31,T_Maint_Innofaso_2[Equipment],F8) -> 6.5 | G31: =SUMIFS(T_Maint_Innofaso_2[Number of hours],T_Maint_Innofaso_2[Année],A31,T_Maint_Innofaso_2[Mois],B31,T_Maint_Innofaso_2[Maintenance Type],C31,T_Maint_Innofaso_2[Equipment],G8) -> 1 | H31: =SUMIFS(T_Maint_Innofaso_2[Number of hours],T_Maint_Innofaso_2[Année],A31,T_Maint_Innofaso_2[Mois],B31,T_Maint_Innofaso_2[Maintenance Type],C31,T_Maint_Innofaso_2[Equipment],H8) -> 1.5 | I31: =SUMIFS(T_Maint_Innofaso_2[Number of hours],T_Maint_Innofaso_2[Année],A31,T_Maint_Innofaso_2[Mois],B31,T_Maint_Innofaso_2[Maintenance Type],C31,T_Maint_Innofaso_2[Equipment],I8) -> 115.17 | J31: =SUMIFS(T_Maint_Innofaso_2[Number of hours],T_Maint_Innofaso_2[Année],A31,T_Maint_Innofaso_2[Mois],B31,T_Maint_Innofaso_2[Maintenance Type],C31,T_Maint_Innofaso_2[Equipment],J8) -> 9 | K31: =SUMIFS(T_Maint_Innofaso_2[Number of hours],T_Maint_Innofaso_2[Année],A31,T_Maint_Innofaso_2[Mois],B31,T_Maint_Innofaso_2[Maintenance Type],C31,T_Maint_Innofaso_2[Equipment],K8) -> 1.5 | L31: =SUMIFS(T_Maint_Innofaso_2[Number of hours],T_Maint_Innofaso_2[Année],A31,T_Maint_Innofaso_2[Mois],B31,T_Maint_Innofaso_2[Maintenance Type],C31,T_Maint_Innofaso_2[Equipment],L8) -> 4 | M31: =SUMIFS(T_Maint_Innofaso_2[Number of hours],T_Maint_Innofaso_2[Année],A31,T_Maint_Innofaso_2[Mois],B31,T_Maint_Innofaso_2[Maintenance Type],C31,T_Maint_Innofaso_2[Equipment],M8) -> 0 | N31: =SUMIFS(T_Maint_Innofaso_2[Number of hours],T_Maint_Innofaso_2[Année],A31,T_Maint_Innofaso_2[Mois],B31,T_Maint_Innofaso_2[Maintenance Type],C31,T_Maint_Innofaso_2[Equipment],N8) -> 0 | O31: =SUMIFS(T_Maint_Innofaso_2[Number of hours],T_Maint_Innofaso_2[Année],A31,T_Maint_Innofaso_2[Mois],B31,T_Maint_Innofaso_2[Maintenance Type],C31,T_Maint_Innofaso_2[Equipment],O8) -> 0 | P31: =SUM(D31:O31) -> 141.67 | Q31: =P31+P32 -> 145.77 | R31: arret en mi-décembre et debut des travaux de maintenance générale.
